/home/cminus-hu/anaconda3/envs/ofa/lib/python3.10/site-packages/torch/distributed/launch.py:181: FutureWarning: The module torch.distributed.launch is deprecated
and will be removed in future. Use torchrun.
Note that --use-env is set by default in torchrun.
If your script expects `--local-rank` argument to be set, please
change it to read from `os.environ['LOCAL_RANK']` instead. See 
https://pytorch.org/docs/stable/distributed.html#launch-utility for 
further instructions

  warnings.warn(
WARNING:torch.distributed.run:
*****************************************
Setting OMP_NUM_THREADS environment variable for each process to be 1 in default, to avoid your system being overloaded, please further tune the variable for optimal performance in your application as needed. 
*****************************************
/home/cminus-hu/anaconda3/envs/ofa/bin/python3: can't open file '/data/cminus-hu/OFA/../../train.py': [Errno 2] No such file or directory
/home/cminus-hu/anaconda3/envs/ofa/bin/python3: can't open file '/data/cminus-hu/OFA/../../train.py': [Errno 2] No such file or directory
/home/cminus-hu/anaconda3/envs/ofa/bin/python3: can't open file '/data/cminus-hu/OFA/../../train.py': [Errno 2] No such file or directory
/home/cminus-hu/anaconda3/envs/ofa/bin/python3: can't open file '/data/cminus-hu/OFA/../../train.py': [Errno 2] No such file or directory
/home/cminus-hu/anaconda3/envs/ofa/bin/python3: can't open file '/data/cminus-hu/OFA/../../train.py': [Errno 2] No such file or directory
ERROR:torch.distributed.elastic.multiprocessing.api:failed (exitcode: 2) local_rank: 0 (pid: 11288) of binary: /home/cminus-hu/anaconda3/envs/ofa/bin/python3
Traceback (most recent call last):
  File "/home/cminus-hu/anaconda3/envs/ofa/lib/python3.10/runpy.py", line 196, in _run_module_as_main
    return _run_code(code, main_globals, None,
  File "/home/cminus-hu/anaconda3/envs/ofa/lib/python3.10/runpy.py", line 86, in _run_code
    exec(code, run_globals)
  File "/home/cminus-hu/anaconda3/envs/ofa/lib/python3.10/site-packages/torch/distributed/launch.py", line 196, in <module>
    main()
  File "/home/cminus-hu/anaconda3/envs/ofa/lib/python3.10/site-packages/torch/distributed/launch.py", line 192, in main
    launch(args)
  File "/home/cminus-hu/anaconda3/envs/ofa/lib/python3.10/site-packages/torch/distributed/launch.py", line 177, in launch
    run(args)
  File "/home/cminus-hu/anaconda3/envs/ofa/lib/python3.10/site-packages/torch/distributed/run.py", line 785, in run
    elastic_launch(
  File "/home/cminus-hu/anaconda3/envs/ofa/lib/python3.10/site-packages/torch/distributed/launcher/api.py", line 134, in __call__
    return launch_agent(self._config, self._entrypoint, list(args))
  File "/home/cminus-hu/anaconda3/envs/ofa/lib/python3.10/site-packages/torch/distributed/launcher/api.py", line 250, in launch_agent
    raise ChildFailedError(
torch.distributed.elastic.multiprocessing.errors.ChildFailedError: 
============================================================
../../train.py FAILED
------------------------------------------------------------
Failures:
[1]:
  time      : 2023-09-04_09:26:08
  host      : stresstest.local.lan
  rank      : 1 (local_rank: 1)
  exitcode  : 2 (pid: 11289)
  error_file: <N/A>
  traceback : To enable traceback see: https://pytorch.org/docs/stable/elastic/errors.html
[2]:
  time      : 2023-09-04_09:26:08
  host      : stresstest.local.lan
  rank      : 2 (local_rank: 2)
  exitcode  : 2 (pid: 11290)
  error_file: <N/A>
  traceback : To enable traceback see: https://pytorch.org/docs/stable/elastic/errors.html
[3]:
  time      : 2023-09-04_09:26:08
  host      : stresstest.local.lan
  rank      : 3 (local_rank: 3)
  exitcode  : 2 (pid: 11291)
  error_file: <N/A>
  traceback : To enable traceback see: https://pytorch.org/docs/stable/elastic/errors.html
[4]:
  time      : 2023-09-04_09:26:08
  host      : stresstest.local.lan
  rank      : 4 (local_rank: 4)
  exitcode  : 2 (pid: 11292)
  error_file: <N/A>
  traceback : To enable traceback see: https://pytorch.org/docs/stable/elastic/errors.html
------------------------------------------------------------
Root Cause (first observed failure):
[0]:
  time      : 2023-09-04_09:26:08
  host      : stresstest.local.lan
  rank      : 0 (local_rank: 0)
  exitcode  : 2 (pid: 11288)
  error_file: <N/A>
  traceback : To enable traceback see: https://pytorch.org/docs/stable/elastic/errors.html
============================================================
/home/cminus-hu/anaconda3/envs/ofa/lib/python3.10/site-packages/torch/distributed/launch.py:181: FutureWarning: The module torch.distributed.launch is deprecated
and will be removed in future. Use torchrun.
Note that --use-env is set by default in torchrun.
If your script expects `--local-rank` argument to be set, please
change it to read from `os.environ['LOCAL_RANK']` instead. See 
https://pytorch.org/docs/stable/distributed.html#launch-utility for 
further instructions

  warnings.warn(
WARNING:torch.distributed.run:
*****************************************
Setting OMP_NUM_THREADS environment variable for each process to be 1 in default, to avoid your system being overloaded, please further tune the variable for optimal performance in your application as needed. 
*****************************************
/home/cminus-hu/anaconda3/envs/ofa/bin/python3: can't open file '/data/cminus-hu/OFA/../../train.py': [Errno 2] No such file or directory
/home/cminus-hu/anaconda3/envs/ofa/bin/python3: can't open file '/data/cminus-hu/OFA/../../train.py': [Errno 2] No such file or directory
/home/cminus-hu/anaconda3/envs/ofa/bin/python3: can't open file '/data/cminus-hu/OFA/../../train.py': [Errno 2] No such file or directory
/home/cminus-hu/anaconda3/envs/ofa/bin/python3: can't open file '/data/cminus-hu/OFA/../../train.py': [Errno 2] No such file or directory
/home/cminus-hu/anaconda3/envs/ofa/bin/python3: can't open file '/data/cminus-hu/OFA/../../train.py': [Errno 2] No such file or directory
ERROR:torch.distributed.elastic.multiprocessing.api:failed (exitcode: 2) local_rank: 0 (pid: 11642) of binary: /home/cminus-hu/anaconda3/envs/ofa/bin/python3
Traceback (most recent call last):
  File "/home/cminus-hu/anaconda3/envs/ofa/lib/python3.10/runpy.py", line 196, in _run_module_as_main
    return _run_code(code, main_globals, None,
  File "/home/cminus-hu/anaconda3/envs/ofa/lib/python3.10/runpy.py", line 86, in _run_code
    exec(code, run_globals)
  File "/home/cminus-hu/anaconda3/envs/ofa/lib/python3.10/site-packages/torch/distributed/launch.py", line 196, in <module>
    main()
  File "/home/cminus-hu/anaconda3/envs/ofa/lib/python3.10/site-packages/torch/distributed/launch.py", line 192, in main
    launch(args)
  File "/home/cminus-hu/anaconda3/envs/ofa/lib/python3.10/site-packages/torch/distributed/launch.py", line 177, in launch
    run(args)
  File "/home/cminus-hu/anaconda3/envs/ofa/lib/python3.10/site-packages/torch/distributed/run.py", line 785, in run
    elastic_launch(
  File "/home/cminus-hu/anaconda3/envs/ofa/lib/python3.10/site-packages/torch/distributed/launcher/api.py", line 134, in __call__
    return launch_agent(self._config, self._entrypoint, list(args))
  File "/home/cminus-hu/anaconda3/envs/ofa/lib/python3.10/site-packages/torch/distributed/launcher/api.py", line 250, in launch_agent
    raise ChildFailedError(
torch.distributed.elastic.multiprocessing.errors.ChildFailedError: 
============================================================
../../train.py FAILED
------------------------------------------------------------
Failures:
[1]:
  time      : 2023-09-04_09:30:02
  host      : stresstest.local.lan
  rank      : 1 (local_rank: 1)
  exitcode  : 2 (pid: 11643)
  error_file: <N/A>
  traceback : To enable traceback see: https://pytorch.org/docs/stable/elastic/errors.html
[2]:
  time      : 2023-09-04_09:30:02
  host      : stresstest.local.lan
  rank      : 2 (local_rank: 2)
  exitcode  : 2 (pid: 11644)
  error_file: <N/A>
  traceback : To enable traceback see: https://pytorch.org/docs/stable/elastic/errors.html
[3]:
  time      : 2023-09-04_09:30:02
  host      : stresstest.local.lan
  rank      : 3 (local_rank: 3)
  exitcode  : 2 (pid: 11645)
  error_file: <N/A>
  traceback : To enable traceback see: https://pytorch.org/docs/stable/elastic/errors.html
[4]:
  time      : 2023-09-04_09:30:02
  host      : stresstest.local.lan
  rank      : 4 (local_rank: 4)
  exitcode  : 2 (pid: 11646)
  error_file: <N/A>
  traceback : To enable traceback see: https://pytorch.org/docs/stable/elastic/errors.html
------------------------------------------------------------
Root Cause (first observed failure):
[0]:
  time      : 2023-09-04_09:30:02
  host      : stresstest.local.lan
  rank      : 0 (local_rank: 0)
  exitcode  : 2 (pid: 11642)
  error_file: <N/A>
  traceback : To enable traceback see: https://pytorch.org/docs/stable/elastic/errors.html
============================================================
/home/cminus-hu/anaconda3/envs/ofa/lib/python3.10/site-packages/torch/distributed/launch.py:181: FutureWarning: The module torch.distributed.launch is deprecated
and will be removed in future. Use torchrun.
Note that --use-env is set by default in torchrun.
If your script expects `--local-rank` argument to be set, please
change it to read from `os.environ['LOCAL_RANK']` instead. See 
https://pytorch.org/docs/stable/distributed.html#launch-utility for 
further instructions

  warnings.warn(
WARNING:torch.distributed.run:
*****************************************
Setting OMP_NUM_THREADS environment variable for each process to be 1 in default, to avoid your system being overloaded, please further tune the variable for optimal performance in your application as needed. 
*****************************************
/home/cminus-hu/anaconda3/envs/ofa/bin/python3: can't open file '/data/cminus-hu/OFA/../../train.py': [Errno 2] No such file or directory
/home/cminus-hu/anaconda3/envs/ofa/bin/python3: can't open file '/data/cminus-hu/OFA/../../train.py': [Errno 2] No such file or directory
/home/cminus-hu/anaconda3/envs/ofa/bin/python3: can't open file '/data/cminus-hu/OFA/../../train.py': [Errno 2] No such file or directory
/home/cminus-hu/anaconda3/envs/ofa/bin/python3: can't open file '/data/cminus-hu/OFA/../../train.py': [Errno 2] No such file or directory
/home/cminus-hu/anaconda3/envs/ofa/bin/python3: can't open file '/data/cminus-hu/OFA/../../train.py': [Errno 2] No such file or directory
ERROR:torch.distributed.elastic.multiprocessing.api:failed (exitcode: 2) local_rank: 0 (pid: 11851) of binary: /home/cminus-hu/anaconda3/envs/ofa/bin/python3
Traceback (most recent call last):
  File "/home/cminus-hu/anaconda3/envs/ofa/lib/python3.10/runpy.py", line 196, in _run_module_as_main
    return _run_code(code, main_globals, None,
  File "/home/cminus-hu/anaconda3/envs/ofa/lib/python3.10/runpy.py", line 86, in _run_code
    exec(code, run_globals)
  File "/home/cminus-hu/anaconda3/envs/ofa/lib/python3.10/site-packages/torch/distributed/launch.py", line 196, in <module>
    main()
  File "/home/cminus-hu/anaconda3/envs/ofa/lib/python3.10/site-packages/torch/distributed/launch.py", line 192, in main
    launch(args)
  File "/home/cminus-hu/anaconda3/envs/ofa/lib/python3.10/site-packages/torch/distributed/launch.py", line 177, in launch
    run(args)
  File "/home/cminus-hu/anaconda3/envs/ofa/lib/python3.10/site-packages/torch/distributed/run.py", line 785, in run
    elastic_launch(
  File "/home/cminus-hu/anaconda3/envs/ofa/lib/python3.10/site-packages/torch/distributed/launcher/api.py", line 134, in __call__
    return launch_agent(self._config, self._entrypoint, list(args))
  File "/home/cminus-hu/anaconda3/envs/ofa/lib/python3.10/site-packages/torch/distributed/launcher/api.py", line 250, in launch_agent
    raise ChildFailedError(
torch.distributed.elastic.multiprocessing.errors.ChildFailedError: 
============================================================
../../train.py FAILED
------------------------------------------------------------
Failures:
[1]:
  time      : 2023-09-04_09:32:49
  host      : stresstest.local.lan
  rank      : 1 (local_rank: 1)
  exitcode  : 2 (pid: 11852)
  error_file: <N/A>
  traceback : To enable traceback see: https://pytorch.org/docs/stable/elastic/errors.html
[2]:
  time      : 2023-09-04_09:32:49
  host      : stresstest.local.lan
  rank      : 2 (local_rank: 2)
  exitcode  : 2 (pid: 11853)
  error_file: <N/A>
  traceback : To enable traceback see: https://pytorch.org/docs/stable/elastic/errors.html
[3]:
  time      : 2023-09-04_09:32:49
  host      : stresstest.local.lan
  rank      : 3 (local_rank: 3)
  exitcode  : 2 (pid: 11854)
  error_file: <N/A>
  traceback : To enable traceback see: https://pytorch.org/docs/stable/elastic/errors.html
[4]:
  time      : 2023-09-04_09:32:49
  host      : stresstest.local.lan
  rank      : 4 (local_rank: 4)
  exitcode  : 2 (pid: 11855)
  error_file: <N/A>
  traceback : To enable traceback see: https://pytorch.org/docs/stable/elastic/errors.html
------------------------------------------------------------
Root Cause (first observed failure):
[0]:
  time      : 2023-09-04_09:32:49
  host      : stresstest.local.lan
  rank      : 0 (local_rank: 0)
  exitcode  : 2 (pid: 11851)
  error_file: <N/A>
  traceback : To enable traceback see: https://pytorch.org/docs/stable/elastic/errors.html
============================================================
/home/cminus-hu/anaconda3/envs/ofa/lib/python3.10/site-packages/torch/distributed/launch.py:181: FutureWarning: The module torch.distributed.launch is deprecated
and will be removed in future. Use torchrun.
Note that --use-env is set by default in torchrun.
If your script expects `--local-rank` argument to be set, please
change it to read from `os.environ['LOCAL_RANK']` instead. See 
https://pytorch.org/docs/stable/distributed.html#launch-utility for 
further instructions

  warnings.warn(
WARNING:torch.distributed.run:
*****************************************
Setting OMP_NUM_THREADS environment variable for each process to be 1 in default, to avoid your system being overloaded, please further tune the variable for optimal performance in your application as needed. 
*****************************************
/home/cminus-hu/anaconda3/envs/ofa/bin/python3: can't open file '/data/cminus-hu/OFA/../../train.py': [Errno 2] No such file or directory
/home/cminus-hu/anaconda3/envs/ofa/bin/python3: can't open file '/data/cminus-hu/OFA/../../train.py': [Errno 2] No such file or directory
/home/cminus-hu/anaconda3/envs/ofa/bin/python3: can't open file '/data/cminus-hu/OFA/../../train.py': [Errno 2] No such file or directory
/home/cminus-hu/anaconda3/envs/ofa/bin/python3: can't open file '/data/cminus-hu/OFA/../../train.py': [Errno 2] No such file or directory
/home/cminus-hu/anaconda3/envs/ofa/bin/python3: can't open file '/data/cminus-hu/OFA/../../train.py': [Errno 2] No such file or directory
ERROR:torch.distributed.elastic.multiprocessing.api:failed (exitcode: 2) local_rank: 0 (pid: 11968) of binary: /home/cminus-hu/anaconda3/envs/ofa/bin/python3
Traceback (most recent call last):
  File "/home/cminus-hu/anaconda3/envs/ofa/lib/python3.10/runpy.py", line 196, in _run_module_as_main
    return _run_code(code, main_globals, None,
  File "/home/cminus-hu/anaconda3/envs/ofa/lib/python3.10/runpy.py", line 86, in _run_code
    exec(code, run_globals)
  File "/home/cminus-hu/anaconda3/envs/ofa/lib/python3.10/site-packages/torch/distributed/launch.py", line 196, in <module>
    main()
  File "/home/cminus-hu/anaconda3/envs/ofa/lib/python3.10/site-packages/torch/distributed/launch.py", line 192, in main
    launch(args)
  File "/home/cminus-hu/anaconda3/envs/ofa/lib/python3.10/site-packages/torch/distributed/launch.py", line 177, in launch
    run(args)
  File "/home/cminus-hu/anaconda3/envs/ofa/lib/python3.10/site-packages/torch/distributed/run.py", line 785, in run
    elastic_launch(
  File "/home/cminus-hu/anaconda3/envs/ofa/lib/python3.10/site-packages/torch/distributed/launcher/api.py", line 134, in __call__
    return launch_agent(self._config, self._entrypoint, list(args))
  File "/home/cminus-hu/anaconda3/envs/ofa/lib/python3.10/site-packages/torch/distributed/launcher/api.py", line 250, in launch_agent
    raise ChildFailedError(
torch.distributed.elastic.multiprocessing.errors.ChildFailedError: 
============================================================
../../train.py FAILED
------------------------------------------------------------
Failures:
[1]:
  time      : 2023-09-04_09:33:17
  host      : stresstest.local.lan
  rank      : 1 (local_rank: 1)
  exitcode  : 2 (pid: 11969)
  error_file: <N/A>
  traceback : To enable traceback see: https://pytorch.org/docs/stable/elastic/errors.html
[2]:
  time      : 2023-09-04_09:33:17
  host      : stresstest.local.lan
  rank      : 2 (local_rank: 2)
  exitcode  : 2 (pid: 11970)
  error_file: <N/A>
  traceback : To enable traceback see: https://pytorch.org/docs/stable/elastic/errors.html
[3]:
  time      : 2023-09-04_09:33:17
  host      : stresstest.local.lan
  rank      : 3 (local_rank: 3)
  exitcode  : 2 (pid: 11971)
  error_file: <N/A>
  traceback : To enable traceback see: https://pytorch.org/docs/stable/elastic/errors.html
[4]:
  time      : 2023-09-04_09:33:17
  host      : stresstest.local.lan
  rank      : 4 (local_rank: 4)
  exitcode  : 2 (pid: 11972)
  error_file: <N/A>
  traceback : To enable traceback see: https://pytorch.org/docs/stable/elastic/errors.html
------------------------------------------------------------
Root Cause (first observed failure):
[0]:
  time      : 2023-09-04_09:33:17
  host      : stresstest.local.lan
  rank      : 0 (local_rank: 0)
  exitcode  : 2 (pid: 11968)
  error_file: <N/A>
  traceback : To enable traceback see: https://pytorch.org/docs/stable/elastic/errors.html
============================================================
/home/cminus-hu/anaconda3/envs/ofa/lib/python3.10/site-packages/torch/distributed/launch.py:181: FutureWarning: The module torch.distributed.launch is deprecated
and will be removed in future. Use torchrun.
Note that --use-env is set by default in torchrun.
If your script expects `--local-rank` argument to be set, please
change it to read from `os.environ['LOCAL_RANK']` instead. See 
https://pytorch.org/docs/stable/distributed.html#launch-utility for 
further instructions

  warnings.warn(
/home/cminus-hu/anaconda3/envs/ofa/bin/python3: can't open file '/data/cminus-hu/OFA/../../train.py': [Errno 2] No such file or directory
ERROR:torch.distributed.elastic.multiprocessing.api:failed (exitcode: 2) local_rank: 0 (pid: 12085) of binary: /home/cminus-hu/anaconda3/envs/ofa/bin/python3
Traceback (most recent call last):
  File "/home/cminus-hu/anaconda3/envs/ofa/lib/python3.10/runpy.py", line 196, in _run_module_as_main
    return _run_code(code, main_globals, None,
  File "/home/cminus-hu/anaconda3/envs/ofa/lib/python3.10/runpy.py", line 86, in _run_code
    exec(code, run_globals)
  File "/home/cminus-hu/anaconda3/envs/ofa/lib/python3.10/site-packages/torch/distributed/launch.py", line 196, in <module>
    main()
  File "/home/cminus-hu/anaconda3/envs/ofa/lib/python3.10/site-packages/torch/distributed/launch.py", line 192, in main
    launch(args)
  File "/home/cminus-hu/anaconda3/envs/ofa/lib/python3.10/site-packages/torch/distributed/launch.py", line 177, in launch
    run(args)
  File "/home/cminus-hu/anaconda3/envs/ofa/lib/python3.10/site-packages/torch/distributed/run.py", line 785, in run
    elastic_launch(
  File "/home/cminus-hu/anaconda3/envs/ofa/lib/python3.10/site-packages/torch/distributed/launcher/api.py", line 134, in __call__
    return launch_agent(self._config, self._entrypoint, list(args))
  File "/home/cminus-hu/anaconda3/envs/ofa/lib/python3.10/site-packages/torch/distributed/launcher/api.py", line 250, in launch_agent
    raise ChildFailedError(
torch.distributed.elastic.multiprocessing.errors.ChildFailedError: 
============================================================
../../train.py FAILED
------------------------------------------------------------
Failures:
  <NO_OTHER_FAILURES>
------------------------------------------------------------
Root Cause (first observed failure):
[0]:
  time      : 2023-09-04_09:33:47
  host      : stresstest.local.lan
  rank      : 0 (local_rank: 0)
  exitcode  : 2 (pid: 12085)
  error_file: <N/A>
  traceback : To enable traceback see: https://pytorch.org/docs/stable/elastic/errors.html
============================================================
python3: can't open file '/data/cminus-hu/OFA/../../train.py': [Errno 2] No such file or directory
python3: can't open file '/data/cminus-hu/OFA/../../train.py': [Errno 2] No such file or directory
/home/cminus-hu/anaconda3/envs/ofa/lib/python3.10/site-packages/torch/distributed/launch.py:181: FutureWarning: The module torch.distributed.launch is deprecated
and will be removed in future. Use torchrun.
Note that --use-env is set by default in torchrun.
If your script expects `--local-rank` argument to be set, please
change it to read from `os.environ['LOCAL_RANK']` instead. See 
https://pytorch.org/docs/stable/distributed.html#launch-utility for 
further instructions

  warnings.warn(
/home/cminus-hu/anaconda3/envs/ofa/bin/python: can't open file '/data/cminus-hu/OFA/../../train.py': [Errno 2] No such file or directory
ERROR:torch.distributed.elastic.multiprocessing.api:failed (exitcode: 2) local_rank: 0 (pid: 12248) of binary: /home/cminus-hu/anaconda3/envs/ofa/bin/python
Traceback (most recent call last):
  File "/home/cminus-hu/anaconda3/envs/ofa/lib/python3.10/runpy.py", line 196, in _run_module_as_main
    return _run_code(code, main_globals, None,
  File "/home/cminus-hu/anaconda3/envs/ofa/lib/python3.10/runpy.py", line 86, in _run_code
    exec(code, run_globals)
  File "/home/cminus-hu/anaconda3/envs/ofa/lib/python3.10/site-packages/torch/distributed/launch.py", line 196, in <module>
    main()
  File "/home/cminus-hu/anaconda3/envs/ofa/lib/python3.10/site-packages/torch/distributed/launch.py", line 192, in main
    launch(args)
  File "/home/cminus-hu/anaconda3/envs/ofa/lib/python3.10/site-packages/torch/distributed/launch.py", line 177, in launch
    run(args)
  File "/home/cminus-hu/anaconda3/envs/ofa/lib/python3.10/site-packages/torch/distributed/run.py", line 785, in run
    elastic_launch(
  File "/home/cminus-hu/anaconda3/envs/ofa/lib/python3.10/site-packages/torch/distributed/launcher/api.py", line 134, in __call__
    return launch_agent(self._config, self._entrypoint, list(args))
  File "/home/cminus-hu/anaconda3/envs/ofa/lib/python3.10/site-packages/torch/distributed/launcher/api.py", line 250, in launch_agent
    raise ChildFailedError(
torch.distributed.elastic.multiprocessing.errors.ChildFailedError: 
============================================================
../../train.py FAILED
------------------------------------------------------------
Failures:
  <NO_OTHER_FAILURES>
------------------------------------------------------------
Root Cause (first observed failure):
[0]:
  time      : 2023-09-04_09:34:36
  host      : stresstest.local.lan
  rank      : 0 (local_rank: 0)
  exitcode  : 2 (pid: 12248)
  error_file: <N/A>
  traceback : To enable traceback see: https://pytorch.org/docs/stable/elastic/errors.html
============================================================
/home/cminus-hu/anaconda3/envs/ofa/lib/python3.10/site-packages/torch/distributed/launch.py:181: FutureWarning: The module torch.distributed.launch is deprecated
and will be removed in future. Use torchrun.
Note that --use-env is set by default in torchrun.
If your script expects `--local-rank` argument to be set, please
change it to read from `os.environ['LOCAL_RANK']` instead. See 
https://pytorch.org/docs/stable/distributed.html#launch-utility for 
further instructions

  warnings.warn(
/home/cminus-hu/anaconda3/envs/ofa/bin/python: can't open file '/data/cminus-hu/ofa/../../train.py': [Errno 2] No such file or directory
ERROR:torch.distributed.elastic.multiprocessing.api:failed (exitcode: 2) local_rank: 0 (pid: 43404) of binary: /home/cminus-hu/anaconda3/envs/ofa/bin/python
Traceback (most recent call last):
  File "/home/cminus-hu/anaconda3/envs/ofa/lib/python3.10/runpy.py", line 196, in _run_module_as_main
    return _run_code(code, main_globals, None,
  File "/home/cminus-hu/anaconda3/envs/ofa/lib/python3.10/runpy.py", line 86, in _run_code
    exec(code, run_globals)
  File "/home/cminus-hu/anaconda3/envs/ofa/lib/python3.10/site-packages/torch/distributed/launch.py", line 196, in <module>
    main()
  File "/home/cminus-hu/anaconda3/envs/ofa/lib/python3.10/site-packages/torch/distributed/launch.py", line 192, in main
    launch(args)
  File "/home/cminus-hu/anaconda3/envs/ofa/lib/python3.10/site-packages/torch/distributed/launch.py", line 177, in launch
    run(args)
  File "/home/cminus-hu/anaconda3/envs/ofa/lib/python3.10/site-packages/torch/distributed/run.py", line 785, in run
    elastic_launch(
  File "/home/cminus-hu/anaconda3/envs/ofa/lib/python3.10/site-packages/torch/distributed/launcher/api.py", line 134, in __call__
    return launch_agent(self._config, self._entrypoint, list(args))
  File "/home/cminus-hu/anaconda3/envs/ofa/lib/python3.10/site-packages/torch/distributed/launcher/api.py", line 250, in launch_agent
    raise ChildFailedError(
torch.distributed.elastic.multiprocessing.errors.ChildFailedError: 
============================================================
../../train.py FAILED
------------------------------------------------------------
Failures:
  <NO_OTHER_FAILURES>
------------------------------------------------------------
Root Cause (first observed failure):
[0]:
  time      : 2023-09-04_13:28:48
  host      : stresstest.local.lan
  rank      : 0 (local_rank: 0)
  exitcode  : 2 (pid: 43404)
  error_file: <N/A>
  traceback : To enable traceback see: https://pytorch.org/docs/stable/elastic/errors.html
============================================================
python: can't open file '/data/cminus-hu/ofa/../../train.py': [Errno 2] No such file or directory
python: can't open file '/data/cminus-hu/ofa/../../train.py': [Errno 2] No such file or directory
/home/cminus-hu/anaconda3/envs/ofa/lib/python3.10/site-packages/torch/distributed/launch.py:181: FutureWarning: The module torch.distributed.launch is deprecated
and will be removed in future. Use torchrun.
Note that --use-env is set by default in torchrun.
If your script expects `--local-rank` argument to be set, please
change it to read from `os.environ['LOCAL_RANK']` instead. See 
https://pytorch.org/docs/stable/distributed.html#launch-utility for 
further instructions

  warnings.warn(
/home/cminus-hu/anaconda3/envs/ofa/bin/python: can't open file '/data/cminus-hu/ofa/../../train.py': [Errno 2] No such file or directory
WARNING:torch.distributed.elastic.agent.server.api:Received 2 death signal, shutting down workers
Traceback (most recent call last):
  File "/home/cminus-hu/anaconda3/envs/ofa/lib/python3.10/runpy.py", line 196, in _run_module_as_main
    return _run_code(code, main_globals, None,
  File "/home/cminus-hu/anaconda3/envs/ofa/lib/python3.10/runpy.py", line 86, in _run_code
    exec(code, run_globals)
  File "/home/cminus-hu/anaconda3/envs/ofa/lib/python3.10/site-packages/torch/distributed/launch.py", line 196, in <module>
    main()
  File "/home/cminus-hu/anaconda3/envs/ofa/lib/python3.10/site-packages/torch/distributed/launch.py", line 192, in main
    launch(args)
  File "/home/cminus-hu/anaconda3/envs/ofa/lib/python3.10/site-packages/torch/distributed/launch.py", line 177, in launch
    run(args)
  File "/home/cminus-hu/anaconda3/envs/ofa/lib/python3.10/site-packages/torch/distributed/run.py", line 785, in run
    elastic_launch(
  File "/home/cminus-hu/anaconda3/envs/ofa/lib/python3.10/site-packages/torch/distributed/launcher/api.py", line 134, in __call__
    return launch_agent(self._config, self._entrypoint, list(args))
  File "/home/cminus-hu/anaconda3/envs/ofa/lib/python3.10/site-packages/torch/distributed/launcher/api.py", line 241, in launch_agent
    result = agent.run()
  File "/home/cminus-hu/anaconda3/envs/ofa/lib/python3.10/site-packages/torch/distributed/elastic/metrics/api.py", line 129, in wrapper
    result = f(*args, **kwargs)
  File "/home/cminus-hu/anaconda3/envs/ofa/lib/python3.10/site-packages/torch/distributed/elastic/agent/server/api.py", line 723, in run
    result = self._invoke_run(role)
  File "/home/cminus-hu/anaconda3/envs/ofa/lib/python3.10/site-packages/torch/distributed/elastic/agent/server/api.py", line 864, in _invoke_run
    time.sleep(monitor_interval)
  File "/home/cminus-hu/anaconda3/envs/ofa/lib/python3.10/site-packages/torch/distributed/elastic/multiprocessing/api.py", line 62, in _terminate_process_handler
    raise SignalException(f"Process {os.getpid()} got signal: {sigval}", sigval=sigval)
torch.distributed.elastic.multiprocessing.api.SignalException: Process 43889 got signal: 2
